Workbook

Sheet Sprint 1
A1: Project name: | C1: THIẾT KẾ VÀ PHÁT TRIỂN NỀN TẢNG HỌC TẬP THÔNG MINH TÍCH HỢP TRỢ LÝ ẢO AI VÀ CÁ NHÂN HOÁ LỘ TRÌNH HỌC TẬP | E1: Kết thúc đúng hạn
A2: Module name: | C2: Sprint 1 | E2: Muộn
A3: Start date: | C3: 22/3/2026 | E3: Trước thời hạn
A4: End date: | C4: 46207
B6: SPRINT 1 REPORT
B7: No | C7: Thành viên | D7: Thực tế | E7: Ước tính
B8: 1 | C8: Trần Duy Dũng | D8: {=SUMPRODUCT( ISNUMBER(SEARCH("All Team",D16:D89))*(E16:E89/5) + ISNUMBER(SEARCH("Dũng",D16:D89))* E16:E89/(LEN(D16:D89)-LEN(SUBSTITUTE(D16:D89,",",""))+1) )} -> 35.3 | E8: {=SUMPRODUCT( ISNUMBER(SEARCH("All Team",D16:D89))*(F16:F89/5) + ISNUMBER(SEARCH("Dũng",D16:D89))* F16:F89/(LEN(D16:D89)-LEN(SUBSTITUTE(D16:D89,",",""))+1) )} -> 35.3
B9: 2 | C9: Trần Thị Thuý Hằng | D9: {=SUMPRODUCT( ISNUMBER(SEARCH("All Team",D16:D89))*(E16:E89/5) + ISNUMBER(SEARCH("Hằng",D16:D89))* E16:E89/(LEN(D16:D89)-LEN(SUBSTITUTE(D16:D89,",",""))+1) )} -> 34.8 | E9: {=SUMPRODUCT( ISNUMBER(SEARCH("All Team",D16:D89))*(F16:F89/5) + ISNUMBER(SEARCH("Hằng",D16:D89))* F16:F89/(LEN(D16:D89)-LEN(SUBSTITUTE(D16:D89,",",""))+1) )} -> 31.8
B10: 3 | C10: Trần Huy Hoàng | D10: {=SUMPRODUCT( ISNUMBER(SEARCH("All Team",D16:D89))*(E16:E89/5) + ISNUMBER(SEARCH("Hoàng",D16:D89))* E16:E89/(LEN(D16:D89)-LEN(SUBSTITUTE(D16:D89,",",""))+1) )} -> 36.3 | E10: {=SUMPRODUCT( ISNUMBER(SEARCH("All Team",D16:D89))*(F16:F89/5) + ISNUMBER(SEARCH("Hoàng",D16:D89))* F16:F89/(LEN(D16:D89)-LEN(SUBSTITUTE(D16:D89,",",""))+1) )} -> 34.3
B11: 4 | C11: Nguyễn Lê Nguyên | D11: {=SUMPRODUCT( ISNUMBER(SEARCH("All Team",D16:D89))*(E16:E89/5) + ISNUMBER(SEARCH("Nguyên",D16:D89))* E16:E89/(LEN(D16:D89)-LEN(SUBSTITUTE(D16:D89,",",""))+1) )} -> 36.8 | E11: {=SUMPRODUCT( ISNUMBER(SEARCH("All Team",D16:D89))*(F16:F89/5) + ISNUMBER(SEARCH("Nguyên",D16:D89))* F16:F89/(LEN(D16:D89)-LEN(SUBSTITUTE(D16:D89,",",""))+1) )} -> 33.8
B12: 5 | C12: Trần Thị Yến Nhi | D12: {=SUMPRODUCT( ISNUMBER(SEARCH("All Team",D16:D89))*(E16:E89/5) + ISNUMBER(SEARCH("Nhi",D16:D89))* E16:E89/(LEN(D16:D89)-LEN(SUBSTITUTE(D16:D89,",",""))+1) )} -> 35.3 | E12: {=SUMPRODUCT( ISNUMBER(SEARCH("All Team",D16:D89))*(F16:F89/5) + ISNUMBER(SEARCH("Nhi",D16:D89))* F16:F89/(LEN(D16:D89)-LEN(SUBSTITUTE(D16:D89,",",""))+1) )} -> 34.8
B13: Tổng | D13: =SUM(D8:D12) -> 178.5 | E13: =SUM(E8:E12) -> 170
A15: Sprint | B15: Compoment | C15: Task name | D15: Responsible Member | E15: Thực tế | F15: Ước tính | G15: 46103 | H15: 46104 | I15: 46105 | J15: 46106 | K15: 46107 | L15: 46108 | M15: 46109 | N15: 46110 | O15: 46111 | P15: 46112 | Q15: 46113 | R15: 46114 | S15: 46115 | T15: 46116 | U15: 46117 | V15: 46118 | W15: 46119
A16: Sprint 1 | B16: Họp kế hoạch Sprint | D16: All Team | E16: =IF(NOT(ISNUMBER(F16)),0, IF(NOT(ISNUMBER(F17)), F16 + IFERROR(INDEX(H17:Z17, MATCH(0, G16:Z16, 0)), 0), F16 ) ) -> 6 | F16: 6 | G16: 0 | H16: 0 | I16: 0 | J16: 0 | K16: 0 | L16: 0 | M16: 0 | N16: 0 | O16: 0 | P16: 0 | Q16: 0 | R16: 0 | S16: 0 | T16: 0 | U16: 0 | V16: 0 | W16: 0
B17: Tạo Sprint Backlog 1 | D17: Hằng, Nhi | E17: =IF(NOT(ISNUMBER(F17)),0, IF(NOT(ISNUMBER(F18)), F17 + IFERROR(INDEX(G18:Z18, MATCH(0, H17:Z17, 0)), 0), F17 ) ) -> 7 | F17: 7 | G17: 5 | H17: 0 | I17: 0 | J17: 0 | K17: 0 | L17: 0 | M17: 0 | N17: 0 | O17: 0 | P17: 0 | Q17: 0 | R17: 0 | S17: 0 | T17: 0 | U17: 0 | V17: 0 | W17: 0
B18: Tạo tài liệu kiểm thử cho Sprint | D18: Nguyên, Hằng | E18: =IF(NOT(ISNUMBER(F18)),0, IF(NOT(ISNUMBER(F19)), F18 + IFERROR(INDEX(G19:Z19, MATCH(0, G18:Z18, 0)), 0), F18 ) ) -> 9 | F18: 7 | G18: 5 | H18: 0 | I18: 0 | J18: 0 | K18: 0 | L18: 0 | M18: 0 | N18: 0 | O18: 0 | P18: 0 | Q18: 0 | R18: 0 | S18: 0 | T18: 0 | U18: 0 | V18: 0 | W18: 0
E19: =IF(NOT(ISNUMBER(F19)),0, IF(NOT(ISNUMBER(F20)), F19 + IFERROR(INDEX(G20:Z20, MATCH(0, G19:Z19, 0)), 0), F19 ) ) -> 0 | H19: 2
B20: User interface design | C20: Đăng ký | D20: Dũng | E20: =IF(NOT(ISNUMBER(F20)),0, IF(NOT(ISNUMBER(F21)), F20 + IFERROR(INDEX(G21:Z21, MATCH(0, G20:Z20, 0)), 0), F20 ) ) -> 2 | F20: 2 | G20: 2 | H20: 2 | I20: 1 | J20: 0 | K20: 0 | L20: 0 | M20: 0 | N20: 0 | O20: 0 | P20: 0 | Q20: 0 | R20: 0 | S20: 0 | T20: 0 | U20: 0 | V20: 0 | W20: 0
C21: Đăng nhập | D21: Dũng | E21: =IF(NOT(ISNUMBER(F21)),0, IF(NOT(ISNUMBER(F22)), F21 + IFERROR(INDEX(G22:Z22, MATCH(0, G21:Z21, 0)), 0), F21 ) ) -> 2 | F21: 2 | G21: 2 | H21: 2 | I21: 1 | J21: 0 | K21: 0 | L21: 0 | M21: 0 | N21: 0 | O21: 0 | P21: 0 | Q21: 0 | R21: 0 | S21: 0 | T21: 0 | U21: 0 | V21: 0 | W21: 0
C22: Tổng quan | D22: Hoàng | E22: =IF(NOT(ISNUMBER(F22)),0, IF(NOT(ISNUMBER(F23)), F22 + IFERROR(INDEX(G23:Z23, MATCH(0, G22:Z22, 0)), 0), F22 ) ) -> 2 | F22: 2 | G22: 2 | H22: 2 | I22: 1 | J22: 0 | K22: 0 | L22: 0 | M22: 0 | N22: 0 | O22: 0 | P22: 0 | Q22: 0 | R22: 0 | S22: 0 | T22: 0 | U22: 0 | V22: 0 | W22: 0
C23: Quên mật khẩu | D23: Hoàng | E23: =IF(NOT(ISNUMBER(F23)),0, IF(NOT(ISNUMBER(F24)), F23 + IFERROR(INDEX(G24:Z24, MATCH(0, G23:Z23, 0)), 0), F23 ) ) -> 2 | F23: 2 | G23: 2 | H23: 2 | I23: 1 | J23: 0 | K23: 0 | L23: 0 | M23: 0 | N23: 0 | O23: 0 | P23: 0 | Q23: 0 | R23: 0 | S23: 0 | T23: 0 | U23: 0 | V23: 0 | W23: 0
C24: Quản lý thông tin cá nhân | D24: Nhi | E24: =IF(NOT(ISNUMBER(F24)),0, IF(NOT(ISNUMBER(F25)), F24 + IFERROR(INDEX(G25:Z25, MATCH(0, G24:Z24, 0)), 0), F24 ) ) -> 1.5 | F24: 2 | G24: 2 | H24: 2 | I24: 1 | J24: 0 | K24: 0 | L24: 0 | M24: 0 | N24: 0 | O24: 0 | P24: 0 | Q24: 0 | R24: 0 | S24: 0 | T24: 0 | U24: 0 | V24: 0 | W24: 0
E25: =IF(NOT(ISNUMBER(F25)),0, IF(NOT(ISNUMBER(F26)), F25 + IFERROR(INDEX(G26:Z26, MATCH(0, G25:Z25, 0)), 0), F25 ) ) -> 0 | J25: -0.5
C26: Quản lý lịch học bằng calendar | D26: Hằng | E26: =IF(NOT(ISNUMBER(F26)),0, IF(NOT(ISNUMBER(F27)), F26 + IFERROR(INDEX(G27:Z27, MATCH(0, G26:Z26, 0)), 0), F26 ) ) -> 2 | F26: 2 | G26: 2 | H26: 2 | I26: 1 | J26: 0 | K26: 0 | L26: 0 | M26: 0 | N26: 0 | O26: 0 | P26: 0 | Q26: 0 | R26: 0 | S26: 0 | T26: 0 | U26: 0 | V26: 0 | W26: 0
C27: Quản lý danh sách công việc (todo-list) với mức độ ưu tiên và trạng thái | D27: Nguyên | E27: =IF(NOT(ISNUMBER(F27)),0, IF(NOT(ISNUMBER(F28)), F27 + IFERROR(INDEX(G28:Z28, MATCH(0, G27:Z27, 0)), 0), F27 ) ) -> 3 | F27: 2 | G27: 2 | H27: 2 | I27: 1 | J27: 0 | K27: 0 | L27: 0 | M27: 0 | N27: 0 | O27: 0 | P27: 0 | Q27: 0 | R27: 0 | S27: 0 | T27: 0 | U27: 0 | V27: 0 | W27: 0
E28: =IF(NOT(ISNUMBER(F28)),0, IF(NOT(ISNUMBER(F29)), F28 + IFERROR(INDEX(G29:Z29, MATCH(0, G28:Z28, 0)), 0), F28 ) ) -> 0 | J28: 1
C29: Review of Sprint 1 | D29: All Team | E29: =IF(NOT(ISNUMBER(F29)),0, IF(NOT(ISNUMBER(F30)), F29 + IFERROR(INDEX(G30:Z30, MATCH(0, G29:Z29, 0)), 0), F29 ) ) -> 6 | F29: 6 | G29: 6 | H29: 6 | I29: 3 | J29: 0 | K29: 0 | L29: 0 | M29: 0 | N29: 0 | O29: 0 | P29: 0 | Q29: 0 | R29: 0 | S29: 0 | T29: 0 | U29: 0 | V29: 0 | W29: 0
B30: Design test case | C30: Đăng ký | D30: Nhi | E30: =IF(NOT(ISNUMBER(F30)),0, IF(NOT(ISNUMBER(F31)), F30 + IFERROR(INDEX(G31:Z31, MATCH(0, G30:Z30, 0)), 0), F30 ) ) -> 2 | F30: 2 | G30: 2 | H30: 2 | I30: 2 | J30: 2 | K30: 1 | L30: 0 | M30: 0 | N30: 0 | O30: 0 | P30: 0 | Q30: 0 | R30: 0 | S30: 0 | T30: 0 | U30: 0 | V30: 0 | W30: 0
C31: Đăng nhập | D31: Nhi | E31: =IF(NOT(ISNUMBER(F31)),0, IF(NOT(ISNUMBER(F32)), F31 + IFERROR(INDEX(G32:Z32, MATCH(0, G31:Z31, 0)), 0), F31 ) ) -> 2 | F31: 2 | G31: 2 | H31: 2 | I31: 2 | J31: 2 | K31: 1 | L31: 0 | M31: 0 | N31: 0 | O31: 0 | P31: 0 | Q31: 0 | R31: 0 | S31: 0 | T31: 0 | U31: 0 | V31: 0 | W31: 0
C32: Tổng quan | D32: Nguyên | E32: =IF(NOT(ISNUMBER(F32)),0, IF(NOT(ISNUMBER(F33)), F32 + IFERROR(INDEX(G33:Z33, MATCH(0, G32:Z32, 0)), 0), F32 ) ) -> 1.5 | F32: 2 | G32: 2 | H32: 2 | I32: 2 | J32: 2 | K32: 1 | L32: 0 | M32: 0 | N32: 0 | O32: 0 | P32: 0 | Q32: 0 | R32: 0 | S32: 0 | T32: 0 | U32: 0 | V32: 0 | W32: 0
E33: =IF(NOT(ISNUMBER(F33)),0, IF(NOT(ISNUMBER(F34)), F33 + IFERROR(INDEX(G34:Z34, MATCH(0, G33:Z33, 0)), 0), F33 ) ) -> 0 | L33: -0.5
C34: Quên mật khẩu | D34: Nguyên | E34: =IF(NOT(ISNUMBER(F34)),0, IF(NOT(ISNUMBER(F35)), F34 + IFERROR(INDEX(G35:Z35, MATCH(0, G34:Z34, 0)), 0), F34 ) ) -> 2 | F34: 2 | G34: 2 | H34: 2 | I34: 2 | J34: 2 | K34: 1 | L34: 0 | M34: 0 | N34: 0 | O34: 0 | P34: 0 | Q34: 0 | R34: 0 | S34: 0 | T34: 0 | U34: 0 | V34: 0 | W34: 0
C35: Quản lý thông tin cá nhân | D35: Hằng | E35: =IF(NOT(ISNUMBER(F35)),0, IF(NOT(ISNUMBER(F36)), F35 + IFERROR(INDEX(G36:Z36, MATCH(0, G35:Z35, 0)), 0), F35 ) ) -> 4 | F35: 2 | G35: 2 | H35: 2 | I35: 2 | J35: 2 | K35: 1 | L35: 0 | M35: 0 | N35: 0 | O35: 0 | P35: 0 | Q35: 0 | R35: 0 | S35: 0 | T35: 0 | U35: 0 | V35: 0 | W35: 0
E36: =IF(NOT(ISNUMBER(F36)),0, IF(NOT(ISNUMBER(F37)), F36 + IFERROR(INDEX(G37:Z37, MATCH(0, G36:Z36, 0)), 0), F36 ) ) -> 0 | L36: 2
C37: Quản lý lịch học bằng calendar | D37: Dũng | E37: =IF(NOT(ISNUMBER(F37)),0, IF(NOT(ISNUMBER(F38)), F37 + IFERROR(INDEX(G38:Z38, MATCH(0, G37:Z37, 0)), 0), F37 ) ) -> 2 | F37: 2 | G37: 2 | H37: 2 | I37: 2 | J37: 2 | K37: 1 | L37: 0 | M37: 0 | N37: 0 | O37: 0 | P37: 0 | Q37: 0 | R37: 0 | S37: 0 | T37: 0 | U37: 0 | V37: 0 | W37: 0
C38: Quản lý danh sách công việc (todo-list) với mức độ ưu tiên và trạng thái | D38: Hoàng | E38: =IF(NOT(ISNUMBER(F38)),0, IF(NOT(ISNUMBER(F39)), F38 + IFERROR(INDEX(G39:Z39, MATCH(0, G38:Z38, 0)), 0), F38 ) ) -> 3 | F38: 2 | G38: 2 | H38: 2 | I38: 2 | J38: 2 | K38: 1 | L38: 0 | M38: 0 | N38: 0 | O38: 0 | P38: 0 | Q38: 0 | R38: 0 | S38: 0 | T38: 0 | U38: 0 | V38: 0 | W38: 0
E39: =IF(NOT(ISNUMBER(F39)),0, IF(NOT(ISNUMBER(F40)), F39 + IFERROR(INDEX(G40:Z40, MATCH(0, G39:Z39, 0)), 0), F39 ) ) -> 0 | L39: 1
C40: Review all test case of Sprint 1 | D40: All Team | E40: =IF(NOT(ISNUMBER(F40)),0, IF(NOT(ISNUMBER(F41)), F40 + IFERROR(INDEX(G41:Z41, MATCH(0, G40:Z40, 0)), 0), F40 ) ) -> 6 | F40: 6 | G40: 6 | H40: 6 | I40: 6 | J40: 6 | K40: 3 | L40: 0 | M40: 0 | N40: 0 | O40: 0 | P40: 0 | Q40: 0 | R40: 0 | S40: 0 | T40: 0 | U40: 0 | V40: 0 | W40: 0
B41: Coding | C41: Code BackEnd Đăng ký | D41: Dũng | E41: =IF(NOT(ISNUMBER(F41)),0, IF(NOT(ISNUMBER(#REF!)), F41 + IFERROR(INDEX(#REF!, MATCH(0, G41:Z41, 0)), 0), F41 ) ) -> 4 | F41: 4 | G41: 4 | H41: 4 | I41: 4 | J41: 4 | K41: 4 | L41: 4 | M41: 2 | N41: 1 | O41: 0 | P41: 0 | Q41: 0 | R41: 0 | S41: 0 | T41: 0 | U41: 0 | V41: 0 | W41: 0
C42: Code BackEnd Đăng nhập | D42: Dũng | E42: =IF(NOT(ISNUMBER(F42)),0, IF(NOT(ISNUMBER(F43)), F42 + IFERROR(INDEX(G43:Z43, MATCH(0, G42:Z42, 0)), 0), F42 ) ) -> 4 | F42: 4 | G42: 4 | H42: 4 | I42: 4 | J42: 4 | K42: 4 | L42: 4 | M42: 2 | N42: 1 | O42: 0 | P42: 0 | Q42: 0 | R42: 0 | S42: 0 | T42: 0 | U42: 0 | V42: 0 | W42: 0
...

Sheet Sprint 2
A1: Project name: | C1: THIẾT KẾ VÀ PHÁT TRIỂN NỀN TẢNG HỌC TẬP THÔNG MINH TÍCH HỢP TRỢ LÝ ẢO AI VÀ CÁ NHÂN HOÁ LỘ TRÌNH HỌC TẬP | E1: Kết thúc đúng hạn
A2: Module name: | C2: Sprint 2 | E2: Muộn
A3: Start date: | C3: 46238 | E3: Trước thời hạn
A4: End date: | C4: 24/4/2026
B6: SPRINT 1 REPORT
B7: No | C7: Thành viên | D7: Thực tế | E7: Ước tính
B8: 1 | C8: Trần Duy Dũng | D8: {=SUMPRODUCT( ISNUMBER(SEARCH("All Team",D16:D70))*(E16:E70/5) + ISNUMBER(SEARCH("Dũng",D16:D70))* E16:E70/(LEN(D16:D70)-LEN(SUBSTITUTE(D16:D70,",",""))+1) )} -> 35.1 | E8: {=SUMPRODUCT( ISNUMBER(SEARCH("All Team",D16:D70))*(F16:F70/5) + ISNUMBER(SEARCH("Dũng",D16:D70))* F16:F70/(LEN(D16:D70)-LEN(SUBSTITUTE(D16:D70,",",""))+1) )} -> 33.6
B9: 2 | C9: Trần Thị Thuý Hằng | D9: {=SUMPRODUCT( ISNUMBER(SEARCH("All Team",D16:D70))*(E16:E70/5) + ISNUMBER(SEARCH("Hằng",D16:D70))* E16:E70/(LEN(D16:D70)-LEN(SUBSTITUTE(D16:D70,",",""))+1) )} -> 35.1 | E9: {=SUMPRODUCT( ISNUMBER(SEARCH("All Team",D16:D70))*(F16:F70/5) + ISNUMBER(SEARCH("Hằng",D16:D70))* F16:F70/(LEN(D16:D70)-LEN(SUBSTITUTE(D16:D70,",",""))+1) )} -> 33.6
B10: 3 | C10: Trần Huy Hoàng | D10: {=SUMPRODUCT( ISNUMBER(SEARCH("All Team",D16:D70))*(E16:E70/5) + ISNUMBER(SEARCH("Hoàng",D16:D70))* E16:E70/(LEN(D16:D70)-LEN(SUBSTITUTE(D16:D70,",",""))+1) )} -> 35.1 | E10: {=SUMPRODUCT( ISNUMBER(SEARCH("All Team",D16:D70))*(F16:F70/5) + ISNUMBER(SEARCH("Hoàng",D16:D70))* F16:F70/(LEN(D16:D70)-LEN(SUBSTITUTE(D16:D70,",",""))+1) )} -> 33.6
B11: 4 | C11: Nguyễn Lê Nguyên | D11: {=SUMPRODUCT( ISNUMBER(SEARCH("All Team",D16:D70))*(E16:E70/5) + ISNUMBER(SEARCH("Nguyên",D16:D70))* E16:E70/(LEN(D16:D70)-LEN(SUBSTITUTE(D16:D70,",",""))+1) )} -> 35.1 | E11: {=SUMPRODUCT( ISNUMBER(SEARCH("All Team",D16:D70))*(F16:F70/5) + ISNUMBER(SEARCH("Nguyên",D16:D70))* F16:F70/(LEN(D16:D70)-LEN(SUBSTITUTE(D16:D70,",",""))+1) )} -> 34.6
B12: 5 | C12: Trần Thị Yến Nhi | D12: {=SUMPRODUCT( ISNUMBER(SEARCH("All Team",D16:D70))*(E16:E70/5) + ISNUMBER(SEARCH("Nhi",D16:D70))* E16:E70/(LEN(D16:D70)-LEN(SUBSTITUTE(D16:D70,",",""))+1) )} -> 35.1 | E12: {=SUMPRODUCT( ISNUMBER(SEARCH("All Team",D16:D70))*(F16:F70/5) + ISNUMBER(SEARCH("Nhi",D16:D70))* F16:F70/(LEN(D16:D70)-LEN(SUBSTITUTE(D16:D70,",",""))+1) )} -> 34.6
B13: Tổng | D13: =SUM(D8:D12) -> 175.5 | E13: =SUM(E8:E12) -> 170
A15: Sprint | B15: Compoment | C15: Task name | D15: Responsible Member | E15: Thực tế | F15: Ước tính | G15: 46120 | H15: 46121 | I15: 46122 | J15: 46123 | K15: 46124 | L15: 46125 | M15: 46126 | N15: 46127 | O15: 46128 | P15: 46129 | Q15: 46130 | R15: 46131 | S15: 46132 | T15: 46133 | U15: 46134 | V15: 46135 | W15: 46136
A16: Sprint 1 | B16: Họp kế hoạch Sprint 2 | D16: All Team | E16: =IF(NOT(ISNUMBER(E17)),0, IF(NOT(ISNUMBER(F17)), F16 + IFERROR(INDEX(G17:W17, MATCH(0, G16:W16, 0)), 0), F16 ) ) -> 8 | F16: 8 | G16: 0 | H16: 0 | I16: 0 | J16: 0 | K16: 0 | L16: 0 | M16: 0 | N16: 0 | O16: 0 | P16: 0 | Q16: 0 | R16: 0 | S16: 0 | T16: 0 | U16: 0 | V16: 0 | W16: 0
B17: Tạo Sprint Backlog 2 | D17: Hằng, Nhi | E17: =IF(NOT(ISNUMBER(E18)),0, IF(NOT(ISNUMBER(F18)), F17 + IFERROR(INDEX(G18:W18, MATCH(0, G17:W17, 0)), 0), F17 ) ) -> 5 | F17: 6 | G17: 4 | H17: 0 | I17: 0 | J17: 0 | K17: 0 | L17: 0 | M17: 0 | N17: 0 | O17: 0 | P17: 0 | Q17: 0 | R17: 0 | S17: 0 | T17: 0 | U17: 0 | V17: 0 | W17: 0
E18: =IF(NOT(ISNUMBER(E19)),0, IF(NOT(ISNUMBER(F19)), F18 + IFERROR(INDEX(G19:W19, MATCH(0, G18:W18, 0)), 0), F18 ) ) -> 0 | H18: -1
B19: Tạo tài liệu kiểm thử cho Sprint 2 | D19: Dũng, Hằng, Hoàng | E19: =IF(NOT(ISNUMBER(E20)),0, IF(NOT(ISNUMBER(F20)), F19 + IFERROR(INDEX(G20:W20, MATCH(0, G19:W19, 0)), 0), F19 ) ) -> 6 | F19: 6 | G19: 6 | H19: 0 | I19: 0 | J19: 0 | K19: 0 | L19: 0 | M19: 0 | N19: 0 | O19: 0 | P19: 0 | Q19: 0 | R19: 0 | S19: 0 | T19: 0 | U19: 0 | V19: 0 | W19: 0
B20: User interface design | C20: Tạo và ôn tập flashcard | D20: Hoàng | E20: =IF(NOT(ISNUMBER(E21)),0, IF(NOT(ISNUMBER(F21)), F20 + IFERROR(INDEX(G21:W21, MATCH(0, G20:W20, 0)), 0), F20 ) ) -> 3 | F20: 3 | G20: 3 | H20: 3 | I20: 1.5 | J20: 0 | K20: 0 | L20: 0 | M20: 0 | N20: 0 | O20: 0 | P20: 0 | Q20: 0 | R20: 0 | S20: 0 | T20: 0 | U20: 0 | V20: 0 | W20: 0
C21: Quản lý tài liệu học tập | D21: Nhi | E21: =IF(NOT(ISNUMBER(E22)),0, IF(NOT(ISNUMBER(F22)), F21 + IFERROR(INDEX(G22:W22, MATCH(0, G21:W21, 0)), 0), F21 ) ) -> 3 | F21: 3 | G21: 3 | H21: 3 | I21: 1.5 | J21: 0 | K21: 0 | L21: 0 | M21: 0 | N21: 0 | O21: 0 | P21: 0 | Q21: 0 | R21: 0 | S21: 0 | T21: 0 | U21: 0 | V21: 0 | W21: 0
C22: Quản lý ghi chú cá nhân | D22: Hằng | E22: =IF(NOT(ISNUMBER(E23)),0, IF(NOT(ISNUMBER(F23)), F22 + IFERROR(INDEX(G23:W23, MATCH(0, G22:W22, 0)), 0), F22 ) ) -> 4 | F22: 3 | G22: 3 | H22: 3 | I22: 1 | J22: 0 | K22: 0 | L22: 0 | M22: 0 | N22: 0 | O22: 0 | P22: 0 | Q22: 0 | R22: 0 | S22: 0 | T22: 0 | U22: 0 | V22: 0 | W22: 0
E23: =IF(NOT(ISNUMBER(E24)),0, IF(NOT(ISNUMBER(F24)), F23 + IFERROR(INDEX(G24:W24, MATCH(0, G23:W23, 0)), 0), F23 ) ) -> 0 | J23: 1
C24: Thống kê và trực quan hóa dữ liệu học tập | D24: Dũng | E24: =IF(NOT(ISNUMBER(E25)),0, IF(NOT(ISNUMBER(F25)), F24 + IFERROR(INDEX(G25:W25, MATCH(0, G24:W24, 0)), 0), F24 ) ) -> 3 | F24: 3 | G24: 3 | H24: 3 | I24: 1.5 | J24: 0 | K24: 0 | L24: 0 | M24: 0 | N24: 0 | O24: 0 | P24: 0 | Q24: 0 | R24: 0 | S24: 0 | T24: 0 | U24: 0 | V24: 0 | W24: 0
C25: Tương tác và nhận hỗ trợ từ chatbot AI | D25: Nguyên | E25: =IF(NOT(ISNUMBER(E26)),0, IF(NOT(ISNUMBER(F26)), F25 + IFERROR(INDEX(G26:W26, MATCH(0, G25:W25, 0)), 0), F25 ) ) -> 4 | F25: 3 | G25: 3 | H25: 3 | I25: 1.5 | J25: 0 | K25: 0 | L25: 0 | M25: 0 | N25: 0 | O25: 0 | P25: 0 | Q25: 0 | R25: 0 | S25: 0 | T25: 0 | U25: 0 | V25: 0 | W25: 0
E26: =IF(NOT(ISNUMBER(E27)),0, IF(NOT(ISNUMBER(F27)), F26 + IFERROR(INDEX(G27:W27, MATCH(0, G26:W26, 0)), 0), F26 ) ) -> 0 | J26: 1
C27: Review of Sprint 2 | D27: All Team | E27: =IF(NOT(ISNUMBER(E28)),0, IF(NOT(ISNUMBER(F28)), F27 + IFERROR(INDEX(G28:W28, MATCH(0, G27:W27, 0)), 0), F27 ) ) -> 5 | F27: 5 | G27: 5 | H27: 5 | I27: 3 | J27: 0 | K27: 0 | L27: 0 | M27: 0 | N27: 0 | O27: 0 | P27: 0 | Q27: 0 | R27: 0 | S27: 0 | T27: 0 | U27: 0 | V27: 0 | W27: 0
B28: Design test case | C28: Tạo và ôn tập flashcard | D28: Nguyên | E28: =IF(NOT(ISNUMBER(E29)),0, IF(NOT(ISNUMBER(F29)), F28 + IFERROR(INDEX(G29:W29, MATCH(0, G28:W28, 0)), 0), F28 ) ) -> 3 | F28: 3 | G28: 3 | H28: 3 | I28: 3 | J28: 3 | K28: 1 | L28: 0 | M28: 0 | N28: 0 | O28: 0 | P28: 0 | Q28: 0 | R28: 0 | S28: 0 | T28: 0 | U28: 0 | V28: 0 | W28: 0
C29: Quản lý tài liệu học tập | D29: Nguyên | E29: =IF(NOT(ISNUMBER(E30)),0, IF(NOT(ISNUMBER(F30)), F29 + IFERROR(INDEX(G30:W30, MATCH(0, G29:W29, 0)), 0), F29 ) ) -> 3 | F29: 3 | G29: 3 | H29: 3 | I29: 3 | J29: 3 | K29: 1 | L29: 0 | M29: 0 | N29: 0 | O29: 0 | P29: 0 | Q29: 0 | R29: 0 | S29: 0 | T29: 0 | U29: 0 | V29: 0 | W29: 0
C30: Quản lý ghi chú cá nhân | D30: Hoàng | E30: =IF(NOT(ISNUMBER(E31)),0, IF(NOT(ISNUMBER(F31)), F30 + IFERROR(INDEX(G31:W31, MATCH(0, G30:W30, 0)), 0), F30 ) ) -> 3 | F30: 3 | G30: 3 | H30: 3 | I30: 3 | J30: 3 | K30: 1 | L30: 0 | M30: 0 | N30: 0 | O30: 0 | P30: 0 | Q30: 0 | R30: 0 | S30: 0 | T30: 0 | U30: 0 | V30: 0 | W30: 0
C31: Thống kê và trực quan hóa dữ liệu học tập | D31: Nhi | E31: =IF(NOT(ISNUMBER(E32)),0, IF(NOT(ISNUMBER(F32)), F31 + IFERROR(INDEX(G32:W32, MATCH(0, G31:W31, 0)), 0), F31 ) ) -> 3 | F31: 3 | G31: 3 | H31: 3 | I31: 3 | J31: 3 | K31: 1 | L31: 0 | M31: 0 | N31: 0 | O31: 0 | P31: 0 | Q31: 0 | R31: 0 | S31: 0 | T31: 0 | U31: 0 | V31: 0 | W31: 0
C32: Tương tác và nhận hỗ trợ từ chatbot AI | D32: Dũng | E32: =IF(NOT(ISNUMBER(E33)),0, IF(NOT(ISNUMBER(F33)), F32 + IFERROR(INDEX(G33:W33, MATCH(0, G32:W32, 0)), 0), F32 ) ) -> 4 | F32: 3 | G32: 3 | H32: 3 | I32: 3 | J32: 3 | K32: 1 | L32: 0 | M32: 0 | N32: 0 | O32: 0 | P32: 0 | Q32: 0 | R32: 0 | S32: 0 | T32: 0 | U32: 0 | V32: 0 | W32: 0
E33: =IF(NOT(ISNUMBER(E34)),0, IF(NOT(ISNUMBER(F34)), F33 + IFERROR(INDEX(G34:W34, MATCH(0, G33:W33, 0)), 0), F33 ) ) -> 0 | L33: 1
C34: Review all test case of Sprint 2 | D34: All Team | E34: =IF(NOT(ISNUMBER(E35)),0, IF(NOT(ISNUMBER(F35)), F34 + IFERROR(INDEX(G35:W35, MATCH(0, G34:W34, 0)), 0), F34 ) ) -> 5 | F34: 5 | G34: 5 | H34: 5 | I34: 5 | J34: 5 | K34: 5 | L34: 0 | M34: 0 | N34: 0 | O34: 0 | P34: 0 | Q34: 0 | R34: 0 | S34: 0 | T34: 0 | U34: 0 | V34: 0 | W34: 0
B35: Coding | C35: Code BackEnd Tạo và ôn tập flashcard | D35: Hoàng | E35: =IF(NOT(ISNUMBER(E36)),0, IF(NOT(ISNUMBER(F36)), F35 + IFERROR(INDEX(G36:W36, MATCH(0, G35:W35, 0)), 0), F35 ) ) -> 5 | F35: 5 | G35: 5 | H35: 5 | I35: 5 | J35: 5 | K35: 5 | L35: 5 | M35: 3 | N35: 1 | O35: 0 | P35: 0 | Q35: 0 | R35: 0 | S35: 0 | T35: 0 | U35: 0 | V35: 0 | W35: 0
C36: Code BackEnd Quản lý tài liệu học tập | D36: Nhi | E36: =IF(NOT(ISNUMBER(E37)),0, IF(NOT(ISNUMBER(F37)), F36 + IFERROR(INDEX(G37:W37, MATCH(0, G36:W36, 0)), 0), F36 ) ) -> 5 | F36: 5 | G36: 5 | H36: 5 | I36: 5 | J36: 5 | K36: 5 | L36: 5 | M36: 3 | N36: 1 | O36: 0 | P36: 0 | Q36: 0 | R36: 0 | S36: 0 | T36: 0 | U36: 0 | V36: 0 | W36: 0
C37: Code BackEnd Quản lý ghi chú cá nhân | D37: Hằng | E37: =IF(NOT(ISNUMBER(E38)),0, IF(NOT(ISNUMBER(F38)), F37 + IFERROR(INDEX(G38:W38, MATCH(0, G37:W37, 0)), 0), F37 ) ) -> 5 | F37: 5 | G37: 5 | H37: 5 | I37: 5 | J37: 5 | K37: 5 | L37: 5 | M37: 3 | N37: 1 | O37: 0 | P37: 0 | Q37: 0 | R37: 0 | S37: 0 | T37: 0 | U37: 0 | V37: 0 | W37: 0
C38: Code BackEnd Thống kê và trực quan hóa dữ liệu học tập | D38: Dũng | E38: =IF(NOT(ISNUMBER(E39)),0, IF(NOT(ISNUMBER(F39)), F38 + IFERROR(INDEX(G39:W39, MATCH(0, G38:W38, 0)), 0), F38 ) ) -> 6 | F38: 5 | G38: 5 | H38: 5 | I38: 5 | J38: 5 | K38: 5 | L38: 5 | M38: 3 | N38: 1 | O38: 0 | P38: 0 | Q38: 0 | R38: 0 | S38: 0 | T38: 0 | U38: 0 | V38: 0 | W38: 0
E39: =IF(NOT(ISNUMBER(E40)),0, IF(NOT(ISNUMBER(F40)), F39 + IFERROR(INDEX(G40:W40, MATCH(0, G39:W39, 0)), 0), F39 ) ) -> 0 | O39: 1
C40: Code BackEnd Xử lý và phản hồi từ chatbot AI | D40: Nguyên | E40: =IF(NOT(ISNUMBER(E41)),0, IF(NOT(ISNUMBER(F41)), F40 + IFERROR(INDEX(G41:W41, MATCH(0, G40:W40, 0)), 0), F40 ) ) -> 5 | F40: 5 | G40: 5 | H40: 5 | I40: 5 | J40: 5 | K40: 5 | L40: 5 | M40: 3 | N40: 1 | O40: 0 | P40: 0 | Q40: 0 | R40: 0 | S40: 0 | T40: 0 | U40: 0 | V40: 0 | W40: 0
C41: Code FrontEnd Tạo và ôn tập flashcard | D41: Hoàng | E41: =IF(NOT(ISNUMBER(E42)),0, IF(NOT(ISNUMBER(F42)), F41 + IFERROR(INDEX(G42:W42, MATCH(0, G41:W41, 0)), 0), F41 ) ) -> 6 | F41: 5 | G41: 5 | H41: 5 | I41: 5 | J41: 5 | K41: 5 | L41: 5 | M41: 5 | N41: 5 | O41: 4 | P41: 2 | Q41: 1 | R41: 0 | S41: 0 | T41: 0 | U41: 0 | V41: 0 | W41: 0
E42: =IF(NOT(ISNUMBER(E43)),0, IF(NOT(ISNUMBER(F43)), F42 + IFERROR(INDEX(G43:W43, MATCH(0, G42:W42, 0)), 0), F42 ) ) -> 0 | R42: 1
...

Sheet Sprint 3
A1: Project name: | C1: THIẾT KẾ VÀ PHÁT TRIỂN NỀN TẢNG HỌC TẬP THÔNG MINH TÍCH HỢP TRỢ LÝ ẢO AI VÀ CÁ NHÂN HOÁ LỘ TRÌNH HỌC TẬP | E1: Kết thúc đúng hạn
A2: Module name: | C2: Sprint 3 | E2: Muộn
A3: Start date: | C3: 25/4/2026 | E3: Trước thời hạn
A4: End date: | C4: 46331
B6: SPRINT 1 REPORT
B7: No | C7: Thành viên | D7: Thực tế | E7: Ước tính
B8: 1 | C8: Trần Duy Dũng | D8: {=SUMPRODUCT( ISNUMBER(SEARCH("All Team",D16:D68))*(E16:E68/5) + ISNUMBER(SEARCH("Dũng",D16:D68))* E16:E68/(LEN(D16:D68)-LEN(SUBSTITUTE(D16:D68,",",""))+1) )} -> 35.1 | E8: {=SUMPRODUCT( ISNUMBER(SEARCH("All Team",D16:D68))*(F16:F68/5) + ISNUMBER(SEARCH("Dũng",D16:D68))* F16:F68/(LEN(D16:D68)-LEN(SUBSTITUTE(D16:D68,",",""))+1) )} -> 33.6
B9: 2 | C9: Trần Thị Thuý Hằng | D9: {=SUMPRODUCT( ISNUMBER(SEARCH("All Team",D16:D68))*(E16:E68/5) + ISNUMBER(SEARCH("Hằng",D16:D68))* E16:E68/(LEN(D16:D68)-LEN(SUBSTITUTE(D16:D68,",",""))+1) )} -> 35.1 | E9: {=SUMPRODUCT( ISNUMBER(SEARCH("All Team",D16:D68))*(F16:F68/5) + ISNUMBER(SEARCH("Hằng",D16:D68))* F16:F68/(LEN(D16:D68)-LEN(SUBSTITUTE(D16:D68,",",""))+1) )} -> 34.6
B10: 3 | C10: Trần Huy Hoàng | D10: {=SUMPRODUCT( ISNUMBER(SEARCH("All Team",D16:D68))*(E16:E68/5) + ISNUMBER(SEARCH("Hoàng",D16:D68))* E16:E68/(LEN(D16:D68)-LEN(SUBSTITUTE(D16:D68,",",""))+1) )} -> 35.6 | E10: {=SUMPRODUCT( ISNUMBER(SEARCH("All Team",D16:D68))*(F16:F68/5) + ISNUMBER(SEARCH("Hoàng",D16:D68))* F16:F68/(LEN(D16:D68)-LEN(SUBSTITUTE(D16:D68,",",""))+1) )} -> 34.6
B11: 4 | C11: Nguyễn Lê Nguyên | D11: {=SUMPRODUCT( ISNUMBER(SEARCH("All Team",D16:D68))*(E16:E68/5) + ISNUMBER(SEARCH("Nguyên",D16:D68))* E16:E68/(LEN(D16:D68)-LEN(SUBSTITUTE(D16:D68,",",""))+1) )} -> 35.1 | E11: {=SUMPRODUCT( ISNUMBER(SEARCH("All Team",D16:D68))*(F16:F68/5) + ISNUMBER(SEARCH("Nguyên",D16:D68))* F16:F68/(LEN(D16:D68)-LEN(SUBSTITUTE(D16:D68,",",""))+1) )} -> 33.6
B12: 5 | C12: Trần Thị Yến Nhi | D12: {=SUMPRODUCT( ISNUMBER(SEARCH("All Team",D16:D68))*(E16:E68/5) + ISNUMBER(SEARCH("Nhi",D16:D68))* E16:E68/(LEN(D16:D68)-LEN(SUBSTITUTE(D16:D68,",",""))+1) )} -> 35.6 | E12: {=SUMPRODUCT( ISNUMBER(SEARCH("All Team",D16:D68))*(F16:F68/5) + ISNUMBER(SEARCH("Nhi",D16:D68))* F16:F68/(LEN(D16:D68)-LEN(SUBSTITUTE(D16:D68,",",""))+1) )} -> 33.6
B13: Tổng | D13: =SUM(D8:D12) -> 176.5 | E13: =SUM(E8:E12) -> 170
A15: Sprint | B15: Compoment | C15: Task name | D15: Responsible Member | E15: Thực tế | F15: Ước tính | G15: 46137 | H15: 46138 | I15: 46139 | J15: 46140 | K15: 46141 | L15: 46142 | M15: 46143 | N15: 46144 | O15: 46145 | P15: 46146 | Q15: 46147 | R15: 46148 | S15: 46149 | T15: 46150 | U15: 46151 | V15: 46152 | W15: 46153
A16: Sprint 3 | B16: Họp kế hoạch Sprint | D16: All Team | E16: =IF(NOT(ISNUMBER(E17)),0, IF(NOT(ISNUMBER(F17)), F16 + IFERROR(INDEX(G17:W17, MATCH(0, G16:W16, 0)), 0), F16 ) ) -> 8 | F16: 8 | G16: 0 | H16: 0 | I16: 0 | J16: 0 | K16: 0 | L16: 0 | M16: 0 | N16: 0 | O16: 0 | P16: 0 | Q16: 0 | R16: 0 | S16: 0 | T16: 0 | U16: 0 | V16: 0 | W16: 0
B17: Tạo Sprint Backlog 3 | D17: Hằng, Hoàng | E17: =IF(NOT(ISNUMBER(E18)),0, IF(NOT(ISNUMBER(F18)), F17 + IFERROR(INDEX(G18:W18, MATCH(0, G17:W17, 0)), 0), F17 ) ) -> 6 | F17: 6 | G17: 5 | H17: 0 | I17: 0 | J17: 0 | K17: 0 | L17: 0 | M17: 0 | N17: 0 | O17: 0 | P17: 0 | Q17: 0 | R17: 0 | S17: 0 | T17: 0 | U17: 0 | V17: 0 | W17: 0
B18: Tạo tài liệu kiểm thử cho Sprint 3 | D18: Nguyên, Dũng, Nhi | E18: =IF(NOT(ISNUMBER(E19)),0, IF(NOT(ISNUMBER(F19)), F18 + IFERROR(INDEX(G19:W19, MATCH(0, G18:W18, 0)), 0), F18 ) ) -> 6 | F18: 6 | G18: 5 | H18: 0 | I18: 0 | J18: 0 | K18: 0 | L18: 0 | M18: 0 | N18: 0 | O18: 0 | P18: 0 | Q18: 0 | R18: 0 | S18: 0 | T18: 0 | U18: 0 | V18: 0 | W18: 0
B19: User interface design | C19: Đăng nhập | D19: Hoàng | E19: =IF(NOT(ISNUMBER(E20)),0, IF(NOT(ISNUMBER(F20)), F19 + IFERROR(INDEX(G20:W20, MATCH(0, G19:W19, 0)), 0), F19 ) ) -> 2 | F19: 2 | G19: 2 | H19: 2 | I19: 1 | J19: 0 | K19: 0 | L19: 0 | M19: 0 | N19: 0 | O19: 0 | P19: 0 | Q19: 0 | R19: 0 | S19: 0 | T19: 0 | U19: 0 | V19: 0 | W19: 0
C20: Tổng quan | D20: Hằng | E20: =IF(NOT(ISNUMBER(E21)),0, IF(NOT(ISNUMBER(F21)), F20 + IFERROR(INDEX(G21:W21, MATCH(0, G20:W20, 0)), 0), F20 ) ) -> 1.5 | F20: 2 | G20: 2 | H20: 2 | I20: 1 | J20: 0 | K20: 0 | L20: 0 | M20: 0 | N20: 0 | O20: 0 | P20: 0 | Q20: 0 | R20: 0 | S20: 0 | T20: 0 | U20: 0 | V20: 0 | W20: 0
E21: =IF(NOT(ISNUMBER(E22)),0, IF(NOT(ISNUMBER(F22)), F21 + IFERROR(INDEX(G22:W22, MATCH(0, G21:W21, 0)), 0), F21 ) ) -> 0 | J21: -0.5
C22: Quản lý tài khoản người dùng | D22: Nguyên | E22: =IF(NOT(ISNUMBER(E23)),0, IF(NOT(ISNUMBER(F23)), F22 + IFERROR(INDEX(G23:W23, MATCH(0, G22:W22, 0)), 0), F22 ) ) -> 2 | F22: 2 | G22: 2 | H22: 2 | I22: 1 | J22: 0 | K22: 0 | L22: 0 | M22: 0 | N22: 0 | O22: 0 | P22: 0 | Q22: 0 | R22: 0 | S22: 0 | T22: 0 | U22: 0 | V22: 0 | W22: 0
C23: Theo dõi hoạt động người dùng | D23: Dũng | E23: =IF(NOT(ISNUMBER(E24)),0, IF(NOT(ISNUMBER(F24)), F23 + IFERROR(INDEX(G24:W24, MATCH(0, G23:W23, 0)), 0), F23 ) ) -> 3 | F23: 2 | G23: 2 | H23: 2 | I23: 1 | J23: 0 | K23: 0 | L23: 0 | M23: 0 | N23: 0 | O23: 0 | P23: 0 | Q23: 0 | R23: 0 | S23: 0 | T23: 0 | U23: 0 | V23: 0 | W23: 0
E24: =IF(NOT(ISNUMBER(E25)),0, IF(NOT(ISNUMBER(F25)), F24 + IFERROR(INDEX(G25:W25, MATCH(0, G24:W24, 0)), 0), F24 ) ) -> 0 | J24: 1
C25: Xem thống kê và báo cáo | D25: Nhi | E25: =IF(NOT(ISNUMBER(E26)),0, IF(NOT(ISNUMBER(F26)), F25 + IFERROR(INDEX(G26:W26, MATCH(0, G25:W25, 0)), 0), F25 ) ) -> 2 | F25: 2 | G25: 2 | H25: 2 | I25: 1 | J25: 0 | K25: 0 | L25: 0 | M25: 0 | N25: 0 | O25: 0 | P25: 0 | Q25: 0 | R25: 0 | S25: 0 | T25: 0 | U25: 0 | V25: 0 | W25: 0
C26: Review of Sprint 3 | D26: All Team | E26: =IF(NOT(ISNUMBER(E27)),0, IF(NOT(ISNUMBER(F27)), F26 + IFERROR(INDEX(G27:W27, MATCH(0, G26:W26, 0)), 0), F26 ) ) -> 10 | F26: 10 | G26: 10 | H26: 10 | I26: 5 | J26: 0 | K26: 0 | L26: 0 | M26: 0 | N26: 0 | O26: 0 | P26: 0 | Q26: 0 | R26: 0 | S26: 0 | T26: 0 | U26: 0 | V26: 0 | W26: 0
B27: Design Test Case | C27: Đăng nhập | D27: Hằng | E27: =IF(NOT(ISNUMBER(E28)),0, IF(NOT(ISNUMBER(F28)), F27 + IFERROR(INDEX(G28:W28, MATCH(0, G27:W27, 0)), 0), F27 ) ) -> 2 | F27: 2 | G27: 2 | H27: 2 | I27: 2 | J27: 2 | K27: 1 | L27: 0 | M27: 0 | N27: 0 | O27: 0 | P27: 0 | Q27: 0 | R27: 0 | S27: 0 | T27: 0 | U27: 0 | V27: 0 | W27: 0
C28: Tổng quan | D28: Dũng | E28: =IF(NOT(ISNUMBER(E29)),0, IF(NOT(ISNUMBER(F29)), F28 + IFERROR(INDEX(G29:W29, MATCH(0, G28:W28, 0)), 0), F28 ) ) -> 2.5 | F28: 2 | G28: 2 | H28: 2 | I28: 2 | J28: 2 | K28: 1 | L28: 0 | M28: 0 | N28: 0 | O28: 0 | P28: 0 | Q28: 0 | R28: 0 | S28: 0 | T28: 0 | U28: 0 | V28: 0 | W28: 0
E29: =IF(NOT(ISNUMBER(E30)),0, IF(NOT(ISNUMBER(F30)), F29 + IFERROR(INDEX(G30:W30, MATCH(0, G29:W29, 0)), 0), F29 ) ) -> 0 | L29: 0.5
C30: Quản lý tài khoản người dùng | D30: Nhi | E30: =IF(NOT(ISNUMBER(E31)),0, IF(NOT(ISNUMBER(F31)), F30 + IFERROR(INDEX(G31:W31, MATCH(0, G30:W30, 0)), 0), F30 ) ) -> 2 | F30: 2 | G30: 2 | H30: 2 | I30: 2 | J30: 2 | K30: 1 | L30: 0 | M30: 0 | N30: 0 | O30: 0 | P30: 0 | Q30: 0 | R30: 0 | S30: 0 | T30: 0 | U30: 0 | V30: 0 | W30: 0
C31: Theo dõi hoạt động người dùng | D31: Hoàng | E31: =IF(NOT(ISNUMBER(E32)),0, IF(NOT(ISNUMBER(F32)), F31 + IFERROR(INDEX(G32:W32, MATCH(0, G31:W31, 0)), 0), F31 ) ) -> 2 | F31: 2 | G31: 2 | H31: 2 | I31: 2 | J31: 2 | K31: 1 | L31: 0 | M31: 0 | N31: 0 | O31: 0 | P31: 0 | Q31: 0 | R31: 0 | S31: 0 | T31: 0 | U31: 0 | V31: 0 | W31: 0
C32: Xem thống kê và báo cáo | D32: Nguyên | E32: =IF(NOT(ISNUMBER(E33)),0, IF(NOT(ISNUMBER(F33)), F32 + IFERROR(INDEX(G33:W33, MATCH(0, G32:W32, 0)), 0), F32 ) ) -> 2 | F32: 2 | G32: 2 | H32: 2 | I32: 2 | J32: 2 | K32: 1 | L32: 0 | M32: 0 | N32: 0 | O32: 0 | P32: 0 | Q32: 0 | R32: 0 | S32: 0 | T32: 0 | U32: 0 | V32: 0 | W32: 0
C33: Review all test case of Sprint 3 | D33: All Team | E33: =IF(NOT(ISNUMBER(E34)),0, IF(NOT(ISNUMBER(F34)), F33 + IFERROR(INDEX(G34:W34, MATCH(0, G33:W33, 0)), 0), F33 ) ) -> 10 | F33: 10 | G33: 10 | H33: 10 | I33: 10 | J33: 10 | K33: 5 | L33: 0 | M33: 0 | N33: 0 | O33: 0 | P33: 0 | Q33: 0 | R33: 0 | S33: 0 | T33: 0 | U33: 0 | V33: 0 | W33: 0
B34: Coding | C34: Code BackEnd Đăng nhập | D34: Hoàng | E34: =IF(NOT(ISNUMBER(E35)),0, IF(NOT(ISNUMBER(F35)), F34 + IFERROR(INDEX(G35:W35, MATCH(0, G34:W34, 0)), 0), F34 ) ) -> 6 | F34: 5 | G34: 5 | H34: 5 | I34: 5 | J34: 5 | K34: 5 | L34: 5 | M34: 3 | N34: 2 | O34: 0 | P34: 0 | Q34: 0 | R34: 0 | S34: 0 | T34: 0 | U34: 0 | V34: 0 | W34: 0
E35: =IF(NOT(ISNUMBER(E36)),0, IF(NOT(ISNUMBER(F36)), F35 + IFERROR(INDEX(G36:W36, MATCH(0, G35:W35, 0)), 0), F35 ) ) -> 0 | O35: 1
C36: Code BackEnd Tổng quan | D36: Hằng | E36: =IF(NOT(ISNUMBER(E37)),0, IF(NOT(ISNUMBER(F37)), F36 + IFERROR(INDEX(G37:W37, MATCH(0, G36:W36, 0)), 0), F36 ) ) -> 6 | F36: 5 | G36: 5 | H36: 5 | I36: 5 | J36: 5 | K36: 5 | L36: 5 | M36: 3 | N36: 1 | O36: 0 | P36: 0 | Q36: 0 | R36: 0 | S36: 0 | T36: 0 | U36: 0 | V36: 0 | W36: 0
E37: =IF(NOT(ISNUMBER(E38)),0, IF(NOT(ISNUMBER(F38)), F37 + IFERROR(INDEX(G38:W38, MATCH(0, G37:W37, 0)), 0), F37 ) ) -> 0 | O37: 1
C38: Code BackEnd Theo dõi hoạt động | D38: Dũng | E38: =IF(NOT(ISNUMBER(E39)),0, IF(NOT(ISNUMBER(F39)), F38 + IFERROR(INDEX(G39:W39, MATCH(0, G38:W38, 0)), 0), F38 ) ) -> 5 | F38: 5 | G38: 5 | H38: 5 | I38: 5 | J38: 5 | K38: 5 | L38: 5 | M38: 3 | N38: 1 | O38: 0 | P38: 0 | Q38: 0 | R38: 0 | S38: 0 | T38: 0 | U38: 0 | V38: 0 | W38: 0
C39: Code BackEnd Thống kê | D39: Nhi | E39: =IF(NOT(ISNUMBER(E40)),0, IF(NOT(ISNUMBER(F40)), F39 + IFERROR(INDEX(G40:W40, MATCH(0, G39:W39, 0)), 0), F39 ) ) -> 5.5 | F39: 5 | G39: 5 | H39: 5 | I39: 5 | J39: 5 | K39: 5 | L39: 5 | M39: 3 | N39: 1 | O39: 0 | P39: 0 | Q39: 0 | R39: 0 | S39: 0 | T39: 0 | U39: 0 | V39: 0 | W39: 0
E40: =IF(NOT(ISNUMBER(E41)),0, IF(NOT(ISNUMBER(F41)), F40 + IFERROR(INDEX(G41:W41, MATCH(0, G40:W40, 0)), 0), F40 ) ) -> 0 | O40: 0.5
C41: Code FrontEnd Đăng nhập | D41: Hoàng | E41: =IF(NOT(ISNUMBER(E42)),0, IF(NOT(ISNUMBER(F42)), F41 + IFERROR(INDEX(G42:W42, MATCH(0, G41:W41, 0)), 0), F41 ) ) -> 5 | F41: 5 | G41: 5 | H41: 5 | I41: 5 | J41: 5 | K41: 5 | L41: 5 | M41: 3 | N41: 1 | O41: 0 | P41: 0 | Q41: 0 | R41: 0 | S41: 0 | T41: 0 | U41: 0 | V41: 0 | W41: 0
C42: Code FrontEnd Tổng quan | D42: Hằng | E42: =IF(NOT(ISNUMBER(E43)),0, IF(NOT(ISNUMBER(F43)), F42 + IFERROR(INDEX(G43:W43, MATCH(0, G42:W42, 0)), 0), F42 ) ) -> 5 | F42: 5 | G42: 5 | H42: 5 | I42: 5 | J42: 5 | K42: 5 | L42: 5 | M42: 5 | N42: 5 | O42: 4.5 | P42: 3.5 | Q42: 1.5 | R42: 0 | S42: 0 | T42: 0 | U42: 0 | V42: 0 | W42: 0
...

Sheet Total
A1: SPRINT BACKLOG REPORT
B2: Dũng | D2: Hằng | F2: Hoàng | H2: Nguyên | J2: Nhi
B3: Thực tế | C3: Ước tính | D3: Thực tế | E3: Ước tính | F3: Thực tế | G3: Ước tính | H3: Thực tế | I3: Ước tính | J3: Thực tế | K3: Ước tính
A4: Sprint 1 | B4: ='Sprint 1'!D8 -> 35.3 | C4: ='Sprint 1'!E8 -> 35.3 | D4: ='Sprint 1'!D9 -> 34.8 | E4: ='Sprint 1'!E9 -> 31.8 | F4: ='Sprint 1'!D10 -> 36.3 | G4: ='Sprint 1'!E10 -> 34.3 | H4: ='Sprint 1'!D11 -> 36.8 | I4: ='Sprint 1'!E11 -> 33.8 | J4: ='Sprint 1'!D12 -> 35.3 | K4: ='Sprint 1'!E12 -> 34.8
A5: Sprint 2 | B5: ='Sprint 2'!D8 -> 35.1 | C5: ='Sprint 2'!E8 -> 33.6 | D5: ='Sprint 2'!D9 -> 35.1 | E5: ='Sprint 2'!E9 -> 33.6 | F5: ='Sprint 2'!D10 -> 35.1 | G5: ='Sprint 2'!E10 -> 33.6 | H5: ='Sprint 2'!D11 -> 35.1 | I5: ='Sprint 2'!E11 -> 34.6 | J5: ='Sprint 2'!D12 -> 35.1 | K5: ='Sprint 2'!E12 -> 34.6
A6: Sprint 3 | B6: ='Sprint 3'!D8 -> 35.1 | C6: ='Sprint 3'!E8 -> 33.6 | D6: ='Sprint 3'!D9 -> 35.1 | E6: ='Sprint 3'!E9 -> 34.6 | F6: ='Sprint 3'!D10 -> 35.6 | G6: ='Sprint 3'!E10 -> 34.6 | H6: ='Sprint 3'!D11 -> 35.1 | I6: ='Sprint 3'!E11 -> 33.6 | J6: ='Sprint 3'!D12 -> 35.6 | K6: ='Sprint 3'!E12 -> 33.6
A7: Tổng | B7: =SUM(B4:B6) -> 105.5 | C7: =SUM(C4:C6) -> 102.5 | D7: =SUM(D4:D6) -> 105 | E7: =SUM(E4:E6) -> 100 | F7: =SUM(F4:F6) -> 107 | G7: =SUM(G4:G6) -> 102.5 | H7: =SUM(H4:H6) -> 107 | I7: =SUM(I4:I6) -> 102 | ... K7: =SUM(K4:K6) -> 103
E10: FINAL TOTAL
E11: Thực tế | F11: =SUMIF($B$3:$K$3,"Thực tế",$B$7:$K$7) -> 530.5
E12: Ước tính | F12: =SUMIF($B$3:$K$3,"Ước tính",$B$7:$K$7) -> 510
