Workbook

Sheet Sprint 1
A1: Project name: | C1: THIẾT KẾ VÀ PHÁT TRIỂN NỀN TẢNG HỌC TẬP THÔNG MINH TÍCH HỢP TRỢ LÝ ẢO AI VÀ CÁ NHÂN HOÁ LỘ TRÌNH HỌC TẬP | E1: Kết thúc đúng hạn
A2: Module name: | C2: Sprint 1 | E2: Muộn
A3: Start date: | C3: 22/3/2026 | E3: Trước thời hạn
A4: End date: | C4: 46207
B6: SPRINT 1 REPORT
B7: No | C7: Thành viên | D7: Thực tế | E7: Ước tính
B8: 1 | C8: Trần Duy Dũng | D8: {=SUMPRODUCT( ISNUMBER(SEARCH("All Team",D16:D87))*(E16:E87/5) + ISNUMBER(SEARCH("Dũng",D16:D87))* E16:E87/(LEN(D16:D87)-LEN(SUBSTITUTE(D16:D87,",",""))+1) )} -> 35.3 | E8: {=SUMPRODUCT( ISNUMBER(SEARCH("All Team",D16:D87))*(F16:F87/5) + ISNUMBER(SEARCH("Dũng",D16:D87))* F16:F87/(LEN(D16:D87)-LEN(SUBSTITUTE(D16:D87,",",""))+1) )} -> 34.3
B9: 2 | C9: Trần Thị Thuý Hằng | D9: {=SUMPRODUCT( ISNUMBER(SEARCH("All Team",D16:D87))*(E16:E87/5) + ISNUMBER(SEARCH("Hằng",D16:D87))* E16:E87/(LEN(D16:D87)-LEN(SUBSTITUTE(D16:D87,",",""))+1) )} -> 32.633333 | E9: {=SUMPRODUCT( ISNUMBER(SEARCH("All Team",D16:D87))*(F16:F87/5) + ISNUMBER(SEARCH("Hằng",D16:D87))* F16:F87/(LEN(D16:D87)-LEN(SUBSTITUTE(D16:D87,",",""))+1) )} -> 31.633333
B10: 3 | C10: Trần Huy Hoàng | D10: {=SUMPRODUCT( ISNUMBER(SEARCH("All Team",D16:D87))*(E16:E87/5) + ISNUMBER(SEARCH("Hoàng",D16:D87))* E16:E87/(LEN(D16:D87)-LEN(SUBSTITUTE(D16:D87,",",""))+1) )} -> 33.633333 | E10: {=SUMPRODUCT( ISNUMBER(SEARCH("All Team",D16:D87))*(F16:F87/5) + ISNUMBER(SEARCH("Hoàng",D16:D87))* F16:F87/(LEN(D16:D87)-LEN(SUBSTITUTE(D16:D87,",",""))+1) )} -> 33.133333
B11: 4 | C11: Nguyễn Lê Nguyên | D11: {=SUMPRODUCT( ISNUMBER(SEARCH("All Team",D16:D87))*(E16:E87/5) + ISNUMBER(SEARCH("Nguyên",D16:D87))* E16:E87/(LEN(D16:D87)-LEN(SUBSTITUTE(D16:D87,",",""))+1) )} -> 35.3 | E11: {=SUMPRODUCT( ISNUMBER(SEARCH("All Team",D16:D87))*(F16:F87/5) + ISNUMBER(SEARCH("Nguyên",D16:D87))* F16:F87/(LEN(D16:D87)-LEN(SUBSTITUTE(D16:D87,",",""))+1) )} -> 33.3
B12: 5 | C12: Trần Thị Yến Nhi | D12: {=SUMPRODUCT( ISNUMBER(SEARCH("All Team",D16:D87))*(E16:E87/5) + ISNUMBER(SEARCH("Nhi",D16:D87))* E16:E87/(LEN(D16:D87)-LEN(SUBSTITUTE(D16:D87,",",""))+1) )} -> 34.633333 | E12: {=SUMPRODUCT( ISNUMBER(SEARCH("All Team",D16:D87))*(F16:F87/5) + ISNUMBER(SEARCH("Nhi",D16:D87))* F16:F87/(LEN(D16:D87)-LEN(SUBSTITUTE(D16:D87,",",""))+1) )} -> 33.633333
B13: Tổng | D13: =SUM(D8:D12) -> 171.5 | E13: =SUM(E8:E12) -> 166
A15: Sprint | B15: Compoment | C15: Task name | D15: Responsible Member | E15: Thực tế | F15: Ước tính | G15: 46103 | H15: 46104 | I15: 46105 | J15: 46106 | K15: 46107 | L15: 46108 | M15: 46109 | N15: 46110 | O15: 46111 | P15: 46112 | Q15: 46113 | R15: 46114 | S15: 46115 | T15: 46116 | U15: 46117 | V15: 46118 | W15: 46119
A16: Sprint 1 | B16: Họp kế hoạch Sprint | D16: All Team | E16: 6 | F16: 6 | G16: 0 | H16: 0 | I16: 0 | J16: 0 | K16: 0 | L16: 0 | M16: 0 | N16: 0 | O16: 0 | P16: 0 | Q16: 0 | R16: 0 | S16: 0 | T16: 0 | U16: 0 | V16: 0 | W16: 0
B17: Tạo Sprint Backlog 1 | D17: Hằng, Hoàng, Nhi | E17: 7 | F17: 7 | G17: 5 | H17: 0 | I17: 0 | J17: 0 | K17: 0 | L17: 0 | M17: 0 | N17: 0 | O17: 0 | P17: 0 | Q17: 0 | R17: 0 | S17: 0 | T17: 0 | U17: 0 | V17: 0 | W17: 0
B18: Tạo tài liệu kiểm thử cho Sprint | D18: Nguyên, Hằng | E18: =F18+I19 -> 9 | F18: 7 | G18: 7 | H18: 2 | I18: 0 | J18: 0 | K18: 0 | L18: 0 | M18: 0 | N18: 0 | O18: 0 | P18: 0 | Q18: 0 | R18: 0 | S18: 0 | T18: 0 | U18: 0 | V18: 0 | W18: 0
I19: 2
B20: User interface design | C20: Đăng ký | D20: Dũng | E20: 2 | F20: 2 | G20: 2 | H20: 2 | I20: 1 | J20: 0 | K20: 0 | L20: 0 | M20: 0 | N20: 0 | O20: 0 | P20: 0 | Q20: 0 | R20: 0 | S20: 0 | T20: 0 | U20: 0 | V20: 0 | W20: 0
C21: Đăng nhập | D21: Dũng | E21: 2 | F21: 2 | G21: 2 | H21: 2 | I21: 1 | J21: 0 | K21: 0 | L21: 0 | M21: 0 | N21: 0 | O21: 0 | P21: 0 | Q21: 0 | R21: 0 | S21: 0 | T21: 0 | U21: 0 | V21: 0 | W21: 0
C22: Đăng xuất | D22: Hoàng | E22: 1 | F22: 1 | G22: 1 | H22: 1 | I22: 1 | J22: 0 | K22: 0 | L22: 0 | M22: 0 | N22: 0 | O22: 0 | P22: 0 | Q22: 0 | R22: 0 | S22: 0 | T22: 0 | U22: 0 | V22: 0 | W22: 0
C23: Quên mật khẩu | D23: Hoàng | E23: 2 | F23: 2 | G23: 2 | H23: 2 | I23: 1 | J23: 0 | K23: 0 | L23: 0 | M23: 0 | N23: 0 | O23: 0 | P23: 0 | Q23: 0 | R23: 0 | S23: 0 | T23: 0 | U23: 0 | V23: 0 | W23: 0
C24: Quản lý thông tin cá nhân | D24: Nhi | E24: 2 | F24: 2 | G24: 2 | H24: 2 | I24: 1 | J24: 0 | K24: 0 | L24: 0 | M24: 0 | N24: 0 | O24: 0 | P24: 0 | Q24: 0 | R24: 0 | S24: 0 | T24: 0 | U24: 0 | V24: 0 | W24: 0
C25: Quản lý lịch học bằng calendar | D25: Hằng | E25: 2 | F25: 2 | G25: 2 | H25: 2 | I25: 1 | J25: 0 | K25: 0 | L25: 0 | M25: 0 | N25: 0 | O25: 0 | P25: 0 | Q25: 0 | R25: 0 | S25: 0 | T25: 0 | U25: 0 | V25: 0 | W25: 0
C26: Quản lý danh sách công việc (todo-list) với mức độ ưu tiên và trạng thái | D26: Nguyên | E26: 3 | F26: 2 | G26: 2 | H26: 2 | I26: 2 | J26: 0 | K26: 0 | L26: 0 | M26: 0 | N26: 0 | O26: 0 | P26: 0 | Q26: 0 | R26: 0 | S26: 0 | T26: 0 | U26: 0 | V26: 0 | W26: 0
J27: 1
C28: Review of Sprint 1 | D28: All Team | E28: 6 | F28: 6 | G28: 6 | H28: 6 | I28: 3 | J28: 0 | K28: 0 | L28: 0 | M28: 0 | N28: 0 | O28: 0 | P28: 0 | Q28: 0 | R28: 0 | S28: 0 | T28: 0 | U28: 0 | V28: 0 | W28: 0
B29: Design test case | C29: Đăng ký | D29: Nhi | E29: 2 | F29: 2 | G29: 2 | H29: 2 | I29: 2 | J29: 2 | K29: 1 | L29: 0 | M29: 0 | N29: 0 | O29: 0 | P29: 0 | Q29: 0 | R29: 0 | S29: 0 | T29: 0 | U29: 0 | V29: 0 | W29: 0
C30: Đăng nhập | D30: Nhi | E30: 2 | F30: 2 | G30: 2 | H30: 2 | I30: 2 | J30: 2 | K30: 1 | L30: 0 | M30: 0 | N30: 0 | O30: 0 | P30: 0 | Q30: 0 | R30: 0 | S30: 0 | T30: 0 | U30: 0 | V30: 0 | W30: 0
C31: Đăng xuất | D31: Nguyên | E31: 1.5 | F31: 2 | G31: 2 | H31: 2 | I31: 2 | J31: 2 | K31: 0 | L31: 0 | M31: 0 | N31: 0 | O31: 0 | P31: 0 | Q31: 0 | R31: 0 | S31: 0 | T31: 0 | U31: 0 | V31: 0 | W31: 0
K32: -0.5
C33: Quên mật khẩu | D33: Nguyên | E33: 2 | F33: 2 | G33: 2 | H33: 2 | I33: 2 | J33: 2 | K33: 1 | L33: 0 | M33: 0 | N33: 0 | O33: 0 | P33: 0 | Q33: 0 | R33: 0 | S33: 0 | T33: 0 | U33: 0 | V33: 0 | W33: 0
C34: Quản lý thông tin cá nhân | D34: Hằng | E34: 1 | F34: 1 | G34: 1 | H34: 1 | I34: 1 | J34: 1 | K34: 1 | L34: 0 | M34: 0 | N34: 0 | O34: 0 | P34: 0 | Q34: 0 | R34: 0 | S34: 0 | T34: 0 | U34: 0 | V34: 0 | W34: 0
C35: Quản lý lịch học bằng calendar | D35: Dũng | E35: 1 | F35: 1 | G35: 1 | H35: 1 | I35: 1 | J35: 1 | K35: 1 | L35: 0 | M35: 0 | N35: 0 | O35: 0 | P35: 0 | Q35: 0 | R35: 0 | S35: 0 | T35: 0 | U35: 0 | V35: 0 | W35: 0
C36: Quản lý danh sách công việc (todo-list) với mức độ ưu tiên và trạng thái | D36: Hoàng | E36: 3 | F36: 2 | G36: 2 | H36: 2 | I36: 2 | J36: 2 | K36: 1 | L36: 0 | M36: 0 | N36: 0 | O36: 0 | P36: 0 | Q36: 0 | R36: 0 | S36: 0 | T36: 0 | U36: 0 | V36: 0 | W36: 0
L37: 1
C38: Review all test case of Sprint 1 | D38: All Team | E38: 6 | F38: 6 | G38: 6 | H38: 6 | I38: 6 | J38: 6 | K38: 4 | L38: 0 | M38: 0 | N38: 0 | O38: 0 | P38: 0 | Q38: 0 | R38: 0 | S38: 0 | T38: 0 | U38: 0 | V38: 0 | W38: 0
B39: Coding | C39: Code BackEnd Đăng ký | D39: Dũng | E39: 5 | F39: 4 | G39: 4 | H39: 4 | I39: 4 | J39: 4 | K39: 4 | L39: 4 | M39: 3 | N39: 0 | O39: 0 | P39: 0 | Q39: 0 | R39: 0 | S39: 0 | T39: 0 | U39: 0 | V39: 0 | W39: 0
N40: 1
C41: Code BackEnd Đăng nhập | D41: Dũng | E41: 4 | F41: 4 | G41: 4 | H41: 4 | I41: 4 | J41: 4 | K41: 4 | L41: 4 | M41: 3 | N41: 0 | O41: 0 | P41: 0 | Q41: 0 | R41: 0 | S41: 0 | T41: 0 | U41: 0 | V41: 0 | W41: 0
C42: Code BackEnd Đăng xuất | D42: Hoàng | E42: 2.5 | F42: 3 | G42: 3 | H42: 3 | I42: 3 | J42: 3 | K42: 3 | L42: 3 | M42: 3 | N42: 0 | O42: 0 | P42: 0 | Q42: 0 | R42: 0 | S42: 0 | T42: 0 | U42: 0 | V42: 0 | W42: 0
...

Sheet Total
A1: SPRINT BACKLOG REPORT
B2: Dũng | D2: Hằng | F2: Hoàng | H2: Nguyên | J2: Nhi
B3: Thực tế | C3: Ước tính | D3: Thực tế | E3: Ước tính | F3: Thực tế | G3: Ước tính | H3: Thực tế | I3: Ước tính | J3: Thực tế | K3: Ước tính
A4: Sprint 1 | B4: ='Sprint 1'!D8 -> 35.3 | C4: ='Sprint 1'!E8 -> 34.3 | D4: ='Sprint 1'!D9 -> 32.633333 | E4: ='Sprint 1'!E9 -> 31.633333 | F4: ='Sprint 1'!D10 -> 33.633333 | G4: ='Sprint 1'!E10 -> 33.133333 | H4: ='Sprint 1'!D11 -> 35.3 | I4: ='Sprint 1'!E11 -> 33.3 | J4: ='Sprint 1'!D12 -> 34.633333 | K4: ='Sprint 1'!E12 -> 33.633333
A5: Sprint 2
A6: Sprint 3
A7: Tổng | B7: =SUM(B4:B6) -> 35.3 | C7: =SUM(C4:C6) -> 34.3 | D7: =SUM(D4:D6) -> 32.633333 | E7: =SUM(E4:E6) -> 31.633333 | F7: =SUM(F4:F6) -> 33.633333 | G7: =SUM(G4:G6) -> 33.133333 | H7: =SUM(H4:H6) -> 35.3 | I7: =SUM(I4:I6) -> 33.3 | ... K7: =SUM(K4:K6) -> 33.633333
E10: FINAL TOTAL
E11: Thực tế | F11: =SUMIF($B$3:$K$3,"Thực tế",$B$7:$K$7) -> 171.5
E12: Ước tính | F12: =SUMIF($B$3:$K$3,"Ước tính",$B$7:$K$7) -> 166
